<robot
  name="hubo_head_description">
  <link
    name="head_base_link">
    <inertial>
      <origin
        xyz="2.47944140397505E-18 -4.99430308017913E-19 0.00499999999999999"
        rpy="0 0 0" />
      <mass
        value="0.0222146018366026" />
      <inertia
        ixx="3.12556116400805E-06"
        ixy="-4.13590306276514E-22"
        ixz="3.23553142549922E-24"
        iyy="6.70889449734138E-06"
        iyz="-6.45912190429717E-22"
        izz="9.46421229740605E-06" />
    </inertial>
    <visual>
      <origin
        xyz="0 0 0"
        rpy="0 0 0" />
      <geometry>
        <mesh
          filename="package://hubo_head_description/meshes/head_base_link.STL" />
      </geometry>
      <material
        name="">
        <color
          rgba="0.792156862745098 0.819607843137255 0.933333333333333 1" />
      </material>
    </visual>
    <collision>
      <origin
        xyz="0 0 0"
        rpy="0 0 0" />
      <geometry>
        <mesh
          filename="package://hubo_head_description/meshes/head_base_link.STL" />
      </geometry>
    </collision>
  </link>
  <link
    name="turret_pan_link">
    <inertial>
      <origin
        xyz="-0.0124044060657886 2.75315905326773E-06 0.0430876541148152"
        rpy="0 0 0" />
      <mass
        value="0.109664559813447" />
      <inertia
        ixx="7.02868228788136E-05"
        ixy="1.05076885956931E-09"
        ixz="9.20519510903004E-06"
        iyy="7.6008855225459E-05"
        iyz="1.55202949215389E-10"
        izz="6.01404094645201E-05" />
    </inertial>
    <visual>
      <origin
        xyz="0 0 0"
        rpy="0 0 0" />
      <geometry>
        <mesh
          filename="package://hubo_head_description/meshes/turret_pan_link.STL" />
      </geometry>
      <material
        name="">
        <color
          rgba="0.792156862745098 0.819607843137255 0.933333333333333 1" />
      </material>
    </visual>
    <collision>
      <origin
        xyz="0 0 0"
        rpy="0 0 0" />
      <geometry>
        <mesh
          filename="package://hubo_head_description/meshes/turret_pan_link.STL" />
      </geometry>
    </collision>
  </link>
  <joint
    name="turret_pan"
    type="continuous">
    <origin
      xyz="0 0 0"
      rpy="0 0 0" />
    <parent
      link="head_base_link" />
    <child
      link="turret_pan_link" />
    <axis
      xyz="0 0 1" />
  </joint>
  <link
    name="turret_tilt_link">
    <inertial>
      <origin
        xyz="0.0120348309295361 -5.66994638401409E-05 0.0515012900325148"
        rpy="0 0 0" />
      <mass
        value="0.570110653946282" />
      <inertia
        ixx="0.00355509505448442"
        ixy="0.000193183393491661"
        ixz="-0.000104055095609269"
        iyy="0.00214381595955743"
        iyz="0.000275255778559809"
        izz="0.0021084485131759" />
    </inertial>
    <visual>
      <origin
        xyz="0 0 0"
        rpy="0 0 0" />
      <geometry>
        <mesh
          filename="package://hubo_head_description/meshes/turret_tilt_link.STL" />
      </geometry>
      <material
        name="">
        <color
          rgba="0.866666666666667 0.909803921568627 1 1" />
      </material>
    </visual>
    <collision>
      <origin
        xyz="0 0 0"
        rpy="0 0 0" />
      <geometry>
        <mesh
          filename="package://hubo_head_description/meshes/turret_tilt_link.STL" />
      </geometry>
    </collision>
  </link>
  <joint
    name="turret_tilt"
    type="continuous">
    <origin
      xyz="0 0 0.081"
      rpy="0 0 0" />
    <parent
      link="turret_pan_link" />
    <child
      link="turret_tilt_link" />
    <axis
      xyz="0 1 0" />
  </joint>
  <link
    name="lidar_tilt_link">
    <inertial>
      <origin
        xyz="-0.000451739713036449 -0.00108059481888049 0.00954086929007916"
        rpy="0 0 0" />
      <mass
        value="0.277440816169479" />
      <inertia
        ixx="0.000287641113004078"
        ixy="-2.1305564731452E-07"
        ixz="-2.79385970666049E-07"
        iyy="0.000278110395242272"
        iyz="-2.60864279304942E-07"
        izz="0.000168609317352167" />
    </inertial>
    <visual>
      <origin
        xyz="0 0 0"
        rpy="0 0 0" />
      <geometry>
        <mesh
          filename="package://hubo_head_description/meshes/lidar_tilt_link.STL" />
      </geometry>
      <material
        name="">
        <color
          rgba="0 0 0 1" />
      </material>
    </visual>
    <collision>
      <origin
        xyz="0 0 0"
        rpy="0 0 0" />
      <geometry>
        <mesh
          filename="package://hubo_head_description/meshes/lidar_tilt_link.STL" />
      </geometry>
    </collision>
  </link>
  <joint
    name="lidar_tilt"
    type="continuous">
    <origin
      xyz="0.062 2.76893912240783E-05 0.03636"
      rpy="0.00276893204593277 -1.38777878078144E-15 0" />
    <parent
      link="turret_tilt_link" />
    <child
      link="lidar_tilt_link" />
    <axis
      xyz="0 1 0.00276892850770753" />
  </joint>
  <link
    name="lidar_optical_frame" />
  <joint
    name="lidar_optical_link"
    type="fixed">
    <origin
      xyz="0 -0.00108907916431705 0.0320031382660522"
      rpy="-0.00276893204593277 1.38777346074552E-15 -3.84266022849734E-18" />
    <parent
      link="lidar_tilt_link" />
    <child
      link="lidar_optical_frame" />
    <axis
      xyz="0 0 0" />
  </joint>
  <link
    name="camera_l_link">
    <inertial>
      <origin
        xyz="0.00514229231739436 3.13965922798531E-05 -0.000183606189565727"
        rpy="0 0 0" />
      <mass
        value="0.0591308426614994" />
      <inertia
        ixx="8.26992338555516E-06"
        ixy="-7.22497181483892E-08"
        ixz="6.1561529634422E-07"
        iyy="4.27928696655449E-05"
        iyz="1.26762308296945E-08"
        izz="4.27623217614253E-05" />
    </inertial>
    <visual>
      <origin
        xyz="0 0 0"
        rpy="0 0 0" />
      <geometry>
        <mesh
          filename="package://hubo_head_description/meshes/flea_camera.STL" />
      </geometry>
      <material
        name="">
        <color
          rgba="0.752941176470588 0.752941176470588 0.752941176470588 1" />
      </material>
    </visual>
    <collision>
      <origin
        xyz="0 0 0"
        rpy="0 0 0" />
      <geometry>
        <mesh
          filename="package://hubo_head_description/meshes/flea_camera.STL" />
      </geometry>
    </collision>
  </link>
  <joint
    name="camera_l"
    type="fixed">
    <origin
      xyz="0.015955 0.0923500000000001 0.14036"
      rpy="0 0 0" />
    <parent
      link="turret_tilt_link" />
    <child
      link="camera_l_link" />
    <axis
      xyz="0 0 0" />
  </joint>
  <link
    name="camera_l_optical_frame" />
  <joint
    name="camera_l_optical"
    type="fixed">
    <origin
      xyz="0 0 0"
      rpy="-1.5707963267949 -9.89729612979842E-16 -1.5707963267949" />
    <parent
      link="camera_l_link" />
    <child
      link="camera_l_optical_frame" />
    <axis
      xyz="0 0 0" />
  </joint>
  <link
    name="camera_c_link">
    <inertial>
      <origin
        xyz="0.00514229248636319 3.13965930811427E-05 -0.000183606178699475"
        rpy="0 0 0" />
      <mass
        value="0.0591308424717379" />
      <inertia
        ixx="8.26992338330723E-06"
        ixy="-7.22497206551064E-08"
        ixz="6.15615262597001E-07"
        iyy="4.27928691375669E-05"
        iyz="1.26762306752925E-08"
        izz="4.27623212356727E-05" />
    </inertial>
    <visual>
      <origin
        xyz="0 0 0"
        rpy="0 0 0" />
      <geometry>
        <mesh
          filename="package://hubo_head_description/meshes/flea_camera.STL" />
      </geometry>
      <material
        name="">
        <color
          rgba="0.752941176470588 0.752941176470588 0.752941176470588 1" />
      </material>
    </visual>
    <collision>
      <origin
        xyz="0 0 0"
        rpy="0 0 0" />
      <geometry>
        <mesh
          filename="package://hubo_head_description/meshes/flea_camera.STL" />
      </geometry>
    </collision>
  </link>
  <joint
    name="camera_c"
    type="fixed">
<!-- 1
    <origin
      xyz="0.02 0.0323500000000001 0.14036"
      rpy="0.015 -0.05 -0.05" />
-->
<!-- Matt 
     xyz="0.0647 0.0243 0.1456"     
     xyz="0.0564 0.0235 0.1491"     

     rpy="0.0136 -0.05256 0.01926"   
     rpy="0.0126 -0.52810 0.01857"   
     rpy="-0.0136 0.05256 -0.01926"  
     rpy="-0.0126 0.52810 -0.01857"  
-->
    <origin
xyz=" 0.05319  0.02597  0.13636"
rpy=" 0.01860 -0.00031  0.00006"
    />

    <parent
      link="turret_tilt_link" />
    <child
      link="camera_c_link" />
    <axis
      xyz="0 0 0" />
  </joint>
  <link
    name="camera_c_optical_frame" />
  <joint
    name="camera_c_optical"
    type="fixed">
    <origin
      xyz="0 0 0"
      rpy="-1.5707963267949 -1.17497412307793E-15 -1.5707963267949" />
    <parent
      link="camera_c_link" />
    <child
      link="camera_c_optical_frame" />
    <axis
      xyz="0 0 0" />
  </joint>
  <link
    name="camera_r_link">
    <inertial>
      <origin
        xyz="0.00514229260483659 3.13965937104033E-05 -0.000183606170741507"
        rpy="0 0 0" />
      <mass
        value="0.0591308423327651" />
      <inertia
        ixx="8.26992338165955E-06"
        ixy="-7.22497225327299E-08"
        ixz="6.15615238892149E-07"
        iyy="4.27928687827889E-05"
        iyz="1.26762305540797E-08"
        izz="4.27623208825232E-05" />
    </inertial>
    <visual>
      <origin
        xyz="0 0 0"
        rpy="0 0 0" />
      <geometry>
        <mesh
          filename="package://hubo_head_description/meshes/flea_camera.STL" />
      </geometry>
      <material
        name="">
        <color
          rgba="0.752941176470588 0.752941176470588 0.752941176470588 1" />
      </material>
    </visual>
    <collision>
      <origin
        xyz="0 0 0"
        rpy="0 0 0" />
      <geometry>
        <mesh
          filename="package://hubo_head_description/meshes/flea_camera.STL" />
      </geometry>
    </collision>
  </link>
  <joint
    name="camera_r"
    type="fixed">
    <origin
      xyz="-0.03 -0.08765 0.14036"
      rpy="0.018 -0.01 0.03" />
    <parent
      link="turret_tilt_link" />
    <child
      link="camera_r_link" />
    <axis
      xyz="0 0 0" />
  </joint>
  <link
    name="camera_r_optical_frame" />
  <joint
    name="camera_r_optical"
    type="fixed">
    <origin
      xyz="0 0 0"
      rpy="-1.5707963267949 -3.50979685635337E-16 -1.5707963267949" />
    <parent
      link="camera_r_link" />
    <child
      link="camera_r_optical_frame" />
    <axis
      xyz="0 0 0" />
  </joint>
</robot>
