<robot
  name="hubo_head_description">
  <link
    name="head_base_link">
    <inertial>
      <origin
        xyz="2.4794E-18 -6.4837E-19 0.005"
        rpy="0 0 0" />
      <mass
        value="0.022215" />
      <inertia
        ixx="3.1256E-06"
        ixy="-3.6189E-22"
        ixz="3.0974E-24"
        iyy="6.7089E-06"
        iyz="-6.4695E-22"
        izz="9.4642E-06" />
    </inertial>
    <visual>
      <origin
        xyz="0 0 0"
        rpy="0 0 0" />
      <geometry>
        <mesh
          filename="package://hubo_head_description/meshes/head_base_link.STL" />
      </geometry>
      <material
        name="">
        <color
          rgba="0.79216 0.81961 0.93333 1" />
      </material>
    </visual>
    <collision>
      <origin
        xyz="0 0 0"
        rpy="0 0 0" />
      <geometry>
        <mesh
          filename="package://hubo_head_description/meshes/head_base_link.STL" />
      </geometry>
    </collision>
  </link>
  <link
    name="turret_pan_link">
    <inertial>
      <origin
        xyz="2.7038E-06 -0.012182 -0.043364"
        rpy="0 0 0" />
      <mass
        value="0.11166" />
      <inertia
        ixx="7.7048E-05"
        ixy="9.8369E-10"
        ixz="-7.1858E-11"
        iyy="7.8518E-05"
        iyz="-9.5807E-06"
        izz="6.8469E-05" />
    </inertial>
    <visual>
      <origin
        xyz="0 0 0"
        rpy="0 0 0" />
      <geometry>
        <mesh
          filename="package://hubo_head_description/meshes/turret_pan_link.STL" />
      </geometry>
      <material
        name="">
        <color
          rgba="0.79216 0.81961 0.93333 1" />
      </material>
    </visual>
    <collision>
      <origin
        xyz="0 0 0"
        rpy="0 0 0" />
      <geometry>
        <mesh
          filename="package://hubo_head_description/meshes/turret_pan_link.STL" />
      </geometry>
    </collision>
  </link>
  <joint
    name="turret_pan"
    type="continuous">
    <origin
      xyz="0 0 0"
      rpy="3.14159265358979 0 1.5707963267949" />
    <parent
      link="head_base_link" />
    <child
      link="turret_pan_link" />
    <axis
      xyz="0 0 -1" />
  </joint>
  <link
    name="turret_tilt_link">
    <inertial>
      <origin
        xyz="-0.0073447 -0.00092257 0.073176"
        rpy="0 0 0" />
      <mass
        value="0.95331" />
      <inertia
        ixx="0.0046918"
        ixy="0.00019613"
        ixz="-0.00047069"
        iyy="0.0038839"
        iyz="0.00025465"
        izz="0.0032127" />
    </inertial>
    <visual>
      <origin
        xyz="0 0 0"
        rpy="0 0 0" />
      <geometry>
        <mesh
          filename="package://hubo_head_description/meshes/turret_tilt_link.STL" />
      </geometry>
      <material
        name="">
        <color
          rgba="0.86667 0.9098 1 1" />
      </material>
    </visual>
    <collision>
      <origin
        xyz="0 0 0"
        rpy="0 0 0" />
      <geometry>
        <mesh
          filename="package://hubo_head_description/meshes/turret_tilt_link.STL" />
      </geometry>
    </collision>
  </link>
  <joint
    name="turret_tilt"
    type="continuous">
    <origin
      xyz="0 0 -0.0755"
      rpy="-3.14159265358979 -1.21972744404619E-16 1.5707963267949" />
    <parent
      link="turret_pan_link" />
    <child
      link="turret_tilt_link" />
    <axis
      xyz="0 1 0" />
  </joint>
  <link
    name="lidar_tilt_link">
    <inertial>
      <origin
        xyz="0.00045174 0.015038 0.0014207"
        rpy="0 0 0" />
      <mass
        value="0.27744" />
      <inertia
        ixx="0.00028764"
        ixy="2.7997E-07"
        ixz="2.1228E-07"
        iyy="0.00016861"
        iyz="-5.6406E-07"
        izz="0.00027811" />
    </inertial>
    <visual>
      <origin
        xyz="0 0 0"
        rpy="0 0 0" />
      <geometry>
        <mesh
          filename="package://hubo_head_description/meshes/lidar_tilt_link.STL" />
      </geometry>
      <material
        name="">
        <color
          rgba="0 0 0 1" />
      </material>
    </visual>
    <collision>
      <origin
        xyz="0 0 0"
        rpy="0 0 0" />
      <geometry>
        <mesh
          filename="package://hubo_head_description/meshes/lidar_tilt_link.STL" />
      </geometry>
    </collision>
  </link>
  <joint
    name="lidar_tilt"
    type="continuous">
    <origin
      xyz="0.062 0 0.03636"
      rpy="1.5707963267949 1.62525199293825E-31 3.14159265358979" />
    <parent
      link="turret_tilt_link" />
    <child
      link="lidar_tilt_link" />
    <axis
      xyz="0 0 -1" />
  </joint>
  <link
    name="camera_l_link">
    <inertial>
      <origin
        xyz="0.0051423 3.1397E-05 -0.00018361"
        rpy="0 0 0" />
      <mass
        value="0.059131" />
      <inertia
        ixx="8.2699E-06"
        ixy="-7.225E-08"
        ixz="6.1562E-07"
        iyy="4.2793E-05"
        iyz="1.2676E-08"
        izz="4.2762E-05" />
    </inertial>
    <visual>
      <origin
        xyz="0 0 0"
        rpy="0 0 0" />
      <geometry>
        <mesh
          filename="package://hubo_head_description/meshes/camera_l_link.STL" />
      </geometry>
      <material
        name="">
        <color
          rgba="0.75294 0.75294 0.75294 1" />
      </material>
    </visual>
    <collision>
      <origin
        xyz="0 0 0"
        rpy="0 0 0" />
      <geometry>
        <mesh
          filename="package://hubo_head_description/meshes/camera_l_link.STL" />
      </geometry>
    </collision>
  </link>
  <joint
    name="camera_l"
    type="fixed">
    <origin
      xyz="0.040455 0.088675 0.14586"
      rpy="0 0 0" />
    <parent
      link="turret_tilt_link" />
    <child
      link="camera_l_link" />
    <axis
      xyz="0 0 0" />
  </joint>
  <link
    name="camera_c_link">
    <inertial>
      <origin
        xyz="0.0051423 3.1397E-05 -0.00018361"
        rpy="0 0 0" />
      <mass
        value="0.059131" />
      <inertia
        ixx="8.2699E-06"
        ixy="-7.225E-08"
        ixz="6.1562E-07"
        iyy="4.2793E-05"
        iyz="1.2676E-08"
        izz="4.2762E-05" />
    </inertial>
    <visual>
      <origin
        xyz="0 0 0"
        rpy="0 0 0" />
      <geometry>
        <mesh
          filename="package://hubo_head_description/meshes/camera_c_link.STL" />
      </geometry>
      <material
        name="">
        <color
          rgba="0.75294 0.75294 0.75294 1" />
      </material>
    </visual>
    <collision>
      <origin
        xyz="0 0 0"
        rpy="0 0 0" />
      <geometry>
        <mesh
          filename="package://hubo_head_description/meshes/camera_c_link.STL" />
      </geometry>
    </collision>
  </link>
  <joint
    name="camera_c"
    type="fixed">
    <origin
      xyz="0.040455 0.028675 0.14586"
      rpy="0 0 0" />
    <parent
      link="turret_tilt_link" />
    <child
      link="camera_c_link" />
    <axis
      xyz="0 0 0" />
  </joint>
  <link
    name="camera_r_link">
    <inertial>
      <origin
        xyz="0.0051423 3.1397E-05 -0.00018361"
        rpy="0 0 0" />
      <mass
        value="0.059131" />
      <inertia
        ixx="8.2699E-06"
        ixy="-7.225E-08"
        ixz="6.1562E-07"
        iyy="4.2793E-05"
        iyz="1.2676E-08"
        izz="4.2762E-05" />
    </inertial>
    <visual>
      <origin
        xyz="0 0 0"
        rpy="0 0 0" />
      <geometry>
        <mesh
          filename="package://hubo_head_description/meshes/camera_r_link.STL" />
      </geometry>
      <material
        name="">
        <color
          rgba="0.75294 0.75294 0.75294 1" />
      </material>
    </visual>
    <collision>
      <origin
        xyz="0 0 0"
        rpy="0 0 0" />
      <geometry>
        <mesh
          filename="package://hubo_head_description/meshes/camera_r_link.STL" />
      </geometry>
    </collision>
  </link>
  <joint
    name="camera_r"
    type="fixed">
    <origin
      xyz="0.040455 -0.091325 0.14586"
      rpy="0 0 0" />
    <parent
      link="turret_tilt_link" />
    <child
      link="camera_r_link" />
    <axis
      xyz="0 0 0" />
  </joint>
  <link
    name="ps_lower_base_link" />
  <joint
    name="ps_lower_base"
    type="fixed">
    <origin
      xyz="-0.067789086884583 -0.00132499999999999 0.125855390601482"
      rpy="8.13589349446095E-16 0.747175452778788 -3.14159265358979" />
    <parent
      link="turret_tilt_link" />
    <child
      link="ps_lower_base_link" />
    <axis
      xyz="0 0 0" />
  </joint>
  <link
    name="ps_upper_base_link" />
  <joint
    name="ps_upper_base"
    type="fixed">
    <origin
      xyz="-0.068045 -0.00132499999999995 0.175676213379847"
      rpy="5.96858314644388E-16 1.04083408558608E-15 3.14159265358979" />
    <parent
      link="turret_tilt_link" />
    <child
      link="ps_upper_base_link" />
    <axis
      xyz="0 0 0" />
  </joint>
</robot>